2025-05-01 22:33:17,453 - gpt_processor_installer_gui - DEBUG - Starting the installer GUI script
2025-05-01 22:35:53,477 - gpt_processor_installer_gui - DEBUG - Starting run_test with install_dir=C:/researcher3rd/test4fpf\filepromptforge, executable_path=C:/researcher3rd/fpf/gpt_processor_main.py
2025-05-01 22:35:53,479 - gpt_processor_installer_gui - ERROR - Input directory not found: [WinError 3] The system cannot find the path specified: 'C:/researcher3rd/test4fpf\\filepromptforge\\input'
2025-05-01 22:35:53,479 - gpt_processor_installer_gui - ERROR - Directory 'C:/researcher3rd/test4fpf\filepromptforge' not found.
2025-05-01 22:35:59,929 - gpt_processor_installer_gui - ERROR - Unexpected error: [WinError 2] The system cannot find the file specified: 'C:/researcher3rd/test4fpf\\filepromptforge'
2025-05-01 22:36:05,515 - gpt_processor_installer_gui - ERROR - Failed to update config file: Config file not found at 'C:/researcher3rd/test4fpf\filepromptforge\default_config.yaml'
2025-05-01 22:36:08,092 - gpt_processor_installer_gui - INFO - Ensured input directory exists at 'C:/researcher3rd/test4fpf\filepromptforge\input'
2025-05-01 22:36:08,092 - gpt_processor_installer_gui - INFO - Ensured output directory exists at 'C:/researcher3rd/test4fpf\filepromptforge\output'
2025-05-01 22:36:08,097 - gpt_processor_installer_gui - INFO - Created default prompt file at 'C:/researcher3rd/test4fpf\filepromptforge\prompts\standard_prompt.txt'.
2025-05-01 22:36:08,097 - gpt_processor_installer_gui - INFO - Created default prompt file at 'C:/researcher3rd/test4fpf\filepromptforge\input\standard_prompt.txt'.
2025-05-01 22:36:08,102 - gpt_processor_installer_gui - INFO - Created default config file at 'C:/researcher3rd/test4fpf\filepromptforge\default_config.yaml'.
2025-05-01 22:36:08,105 - gpt_processor_installer_gui - INFO - Copied main executable to 'C:/researcher3rd/test4fpf\filepromptforge'.
2025-05-01 22:36:08,105 - gpt_processor_installer_gui - INFO - Added 'C:/researcher3rd/test4fpf\filepromptforge' to the system PATH.
2025-05-01 22:36:08,106 - gpt_processor_installer_gui - INFO - GPT Processor installation completed successfully in C:/researcher3rd/test4fpf\filepromptforge
2025-05-01 22:36:11,276 - gpt_processor_installer_gui - INFO - Ensured input directory exists at 'C:/researcher3rd/test4fpf\filepromptforge\input'
2025-05-01 22:36:11,276 - gpt_processor_installer_gui - INFO - Ensured output directory exists at 'C:/researcher3rd/test4fpf\filepromptforge\output'
2025-05-01 22:36:11,276 - gpt_processor_installer_gui - INFO - Created default prompt file at 'C:/researcher3rd/test4fpf\filepromptforge\prompts\standard_prompt.txt'.
2025-05-01 22:36:11,276 - gpt_processor_installer_gui - INFO - Created default prompt file at 'C:/researcher3rd/test4fpf\filepromptforge\input\standard_prompt.txt'.
2025-05-01 22:36:11,282 - gpt_processor_installer_gui - INFO - Created default config file at 'C:/researcher3rd/test4fpf\filepromptforge\default_config.yaml'.
2025-05-01 22:36:11,284 - gpt_processor_installer_gui - INFO - Copied main executable to 'C:/researcher3rd/test4fpf\filepromptforge'.
2025-05-01 22:36:11,284 - gpt_processor_installer_gui - INFO - 'C:/researcher3rd/test4fpf\filepromptforge' is already in the system PATH.
2025-05-01 22:36:11,284 - gpt_processor_installer_gui - INFO - GPT Processor installation completed successfully in C:/researcher3rd/test4fpf\filepromptforge
2025-05-01 22:36:18,802 - gpt_processor_installer_gui - INFO - Ensured input directory exists at 'C:/researcher3rd/test4fpf\filepromptforge\input'
2025-05-01 22:36:18,802 - gpt_processor_installer_gui - INFO - Ensured output directory exists at 'C:/researcher3rd/test4fpf\filepromptforge\output'
2025-05-01 22:36:18,802 - gpt_processor_installer_gui - INFO - Created default prompt file at 'C:/researcher3rd/test4fpf\filepromptforge\prompts\standard_prompt.txt'.
2025-05-01 22:36:18,807 - gpt_processor_installer_gui - INFO - Created default prompt file at 'C:/researcher3rd/test4fpf\filepromptforge\input\standard_prompt.txt'.
2025-05-01 22:36:18,807 - gpt_processor_installer_gui - INFO - Created default config file at 'C:/researcher3rd/test4fpf\filepromptforge\default_config.yaml'.
2025-05-01 22:36:18,807 - gpt_processor_installer_gui - INFO - Copied main executable to 'C:/researcher3rd/test4fpf\filepromptforge'.
2025-05-01 22:36:18,807 - gpt_processor_installer_gui - INFO - 'C:/researcher3rd/test4fpf\filepromptforge' is already in the system PATH.
2025-05-01 22:36:18,807 - gpt_processor_installer_gui - INFO - GPT Processor installation completed successfully in C:/researcher3rd/test4fpf\filepromptforge
2025-05-01 22:36:20,369 - gpt_processor_installer_gui - DEBUG - Starting run_test with install_dir=C:/researcher3rd/test4fpf\filepromptforge, executable_path=C:/researcher3rd/fpf/gpt_processor_main.py
2025-05-01 22:36:20,374 - gpt_processor_installer_gui - DEBUG - Input directory contents: ['standard_prompt.txt']
2025-05-01 22:36:20,374 - gpt_processor_installer_gui - DEBUG - Running command: ['python', 'C:/researcher3rd/fpf/gpt_processor_main.py', '--prompt', 'C:/researcher3rd/test4fpf\\filepromptforge\\prompts\\standard_prompt.txt', '--input_dir', 'C:/researcher3rd/test4fpf\\filepromptforge\\input', '--output_dir', 'C:/researcher3rd/test4fpf\\filepromptforge\\output']
2025-05-01 22:36:22,171 - gpt_processor_installer_gui - DEBUG - Command output: 
2025-05-01 22:36:22,176 - gpt_processor_installer_gui - DEBUG - Command error: Traceback (most recent call last):
  File "C:\researcher3rd\fpf\gpt_processor_main.py", line 19, in <module>
    from openai.error import OpenAIError, RateLimitError
ModuleNotFoundError: No module named 'openai.error'

2025-05-01 22:36:22,176 - gpt_processor_installer_gui - ERROR - Subprocess error: Command '['python', 'C:/researcher3rd/fpf/gpt_processor_main.py', '--prompt', 'C:/researcher3rd/test4fpf\\filepromptforge\\prompts\\standard_prompt.txt', '--input_dir', 'C:/researcher3rd/test4fpf\\filepromptforge\\input', '--output_dir', 'C:/researcher3rd/test4fpf\\filepromptforge\\output']' returned non-zero exit status 1.
2025-05-01 22:36:22,176 - gpt_processor_installer_gui - ERROR - Command output: 
2025-05-01 22:36:22,176 - gpt_processor_installer_gui - ERROR - Command stderr: Traceback (most recent call last):
  File "C:\researcher3rd\fpf\gpt_processor_main.py", line 19, in <module>
    from openai.error import OpenAIError, RateLimitError
ModuleNotFoundError: No module named 'openai.error'

2025-05-01 22:36:29,367 - gpt_processor_installer_gui - INFO - Updated config file at 'C:/researcher3rd/test4fpf\filepromptforge\default_config.yaml' with model 'gpt-4o-mini'
2025-05-01 22:37:40,580 - gpt_processor_installer_gui - DEBUG - Starting run_test with install_dir=C:/researcher3rd/test4fpf\filepromptforge, executable_path=C:/researcher3rd/fpf/gpt_processor_main.py
2025-05-01 22:37:40,580 - gpt_processor_installer_gui - DEBUG - Input directory contents: ['standard_prompt.txt']
2025-05-01 22:37:40,580 - gpt_processor_installer_gui - DEBUG - Running command: ['python', 'C:/researcher3rd/fpf/gpt_processor_main.py', '--prompt', 'C:/researcher3rd/test4fpf\\filepromptforge\\prompts\\standard_prompt.txt', '--input_dir', 'C:/researcher3rd/test4fpf\\filepromptforge\\input', '--output_dir', 'C:/researcher3rd/test4fpf\\filepromptforge\\output']
2025-05-01 22:37:42,079 - gpt_processor_installer_gui - DEBUG - Command output: 
2025-05-01 22:37:42,084 - gpt_processor_installer_gui - DEBUG - Command error: Traceback (most recent call last):
  File "C:\researcher3rd\fpf\gpt_processor_main.py", line 19, in <module>
    from openai.error import OpenAIError, RateLimitError
ModuleNotFoundError: No module named 'openai.error'

2025-05-01 22:37:42,084 - gpt_processor_installer_gui - ERROR - Subprocess error: Command '['python', 'C:/researcher3rd/fpf/gpt_processor_main.py', '--prompt', 'C:/researcher3rd/test4fpf\\filepromptforge\\prompts\\standard_prompt.txt', '--input_dir', 'C:/researcher3rd/test4fpf\\filepromptforge\\input', '--output_dir', 'C:/researcher3rd/test4fpf\\filepromptforge\\output']' returned non-zero exit status 1.
2025-05-01 22:37:42,085 - gpt_processor_installer_gui - ERROR - Command output: 
2025-05-01 22:37:42,086 - gpt_processor_installer_gui - ERROR - Command stderr: Traceback (most recent call last):
  File "C:\researcher3rd\fpf\gpt_processor_main.py", line 19, in <module>
    from openai.error import OpenAIError, RateLimitError
ModuleNotFoundError: No module named 'openai.error'

