2025-05-01 22:42:49,583 - gpt_processor_installer_gui - DEBUG - Starting the installer GUI script
2025-05-01 22:43:18,164 - gpt_processor_installer_gui - INFO - Ensured input directory exists at 'C:/researcher3rd/test4fpf\filepromptforge\input'
2025-05-01 22:43:18,164 - gpt_processor_installer_gui - INFO - Ensured output directory exists at 'C:/researcher3rd/test4fpf\filepromptforge\output'
2025-05-01 22:43:18,164 - gpt_processor_installer_gui - INFO - Created default prompt file at 'C:/researcher3rd/test4fpf\filepromptforge\prompts\standard_prompt.txt'.
2025-05-01 22:43:18,164 - gpt_processor_installer_gui - INFO - Created default prompt file at 'C:/researcher3rd/test4fpf\filepromptforge\input\standard_prompt.txt'.
2025-05-01 22:43:18,169 - gpt_processor_installer_gui - INFO - Created default config file at 'C:/researcher3rd/test4fpf\filepromptforge\default_config.yaml'.
2025-05-01 22:43:18,169 - gpt_processor_installer_gui - INFO - Copied main executable to 'C:/researcher3rd/test4fpf\filepromptforge'.
2025-05-01 22:43:18,169 - gpt_processor_installer_gui - INFO - Added 'C:/researcher3rd/test4fpf\filepromptforge' to the system PATH.
2025-05-01 22:43:20,504 - gpt_processor_installer_gui - DEBUG - Dependency install stdout: Defaulting to user installation because normal site-packages is not writeable
Requirement already satisfied: openai in c:\users\administrator\appdata\roaming\python\python312\site-packages (1.76.0)
Requirement already satisfied: anyio<5,>=3.5.0 in c:\users\administrator\appdata\roaming\python\python312\site-packages (from openai) (4.6.2.post1)
Requirement already satisfied: distro<2,>=1.7.0 in c:\users\administrator\appdata\roaming\python\python312\site-packages (from openai) (1.9.0)
Requirement already satisfied: httpx<1,>=0.23.0 in c:\users\administrator\appdata\roaming\python\python312\site-packages (from openai) (0.28.1)
Requirement already satisfied: jiter<1,>=0.4.0 in c:\users\administrator\appdata\roaming\python\python312\site-packages (from openai) (0.6.1)
Requirement already satisfied: pydantic<3,>=1.9.0 in c:\users\administrator\appdata\roaming\python\python312\site-packages (from openai) (2.11.3)
Requirement already satisfied: sniffio in c:\users\administrator\appdata\roaming\python\python312\site-packages (from openai) (1.3.1)
Requirement already satisfied: tqdm>4 in c:\users\administrator\appdata\roaming\python\python312\site-packages (from openai) (4.66.5)
Requirement already satisfied: typing-extensions<5,>=4.11 in c:\users\administrator\appdata\roaming\python\python312\site-packages (from openai) (4.12.2)
Requirement already satisfied: idna>=2.8 in c:\users\administrator\appdata\roaming\python\python312\site-packages (from anyio<5,>=3.5.0->openai) (3.10)
Requirement already satisfied: certifi in c:\users\administrator\appdata\roaming\python\python312\site-packages (from httpx<1,>=0.23.0->openai) (2025.4.26)
Requirement already satisfied: httpcore==1.* in c:\users\administrator\appdata\roaming\python\python312\site-packages (from httpx<1,>=0.23.0->openai) (1.0.6)
Requirement already satisfied: h11<0.15,>=0.13 in c:\users\administrator\appdata\roaming\python\python312\site-packages (from httpcore==1.*->httpx<1,>=0.23.0->openai) (0.14.0)
Requirement already satisfied: annotated-types>=0.6.0 in c:\users\administrator\appdata\roaming\python\python312\site-packages (from pydantic<3,>=1.9.0->openai) (0.7.0)
Requirement already satisfied: pydantic-core==2.33.1 in c:\users\administrator\appdata\roaming\python\python312\site-packages (from pydantic<3,>=1.9.0->openai) (2.33.1)
Requirement already satisfied: typing-inspection>=0.4.0 in c:\users\administrator\appdata\roaming\python\python312\site-packages (from pydantic<3,>=1.9.0->openai) (0.4.0)
Requirement already satisfied: colorama in c:\users\administrator\appdata\roaming\python\python312\site-packages (from tqdm>4->openai) (0.4.6)

2025-05-01 22:43:20,504 - gpt_processor_installer_gui - DEBUG - Dependency install stderr: 
[notice] A new release of pip is available: 24.3.1 -> 25.1
[notice] To update, run: python.exe -m pip install --upgrade pip

2025-05-01 22:43:20,504 - gpt_processor_installer_gui - INFO - Installed openai package successfully.
2025-05-01 22:43:20,504 - gpt_processor_installer_gui - INFO - GPT Processor installation completed successfully in C:/researcher3rd/test4fpf\filepromptforge
2025-05-01 22:43:31,780 - gpt_processor_installer_gui - DEBUG - Starting run_test with install_dir=C:/researcher3rd/test4fpf\filepromptforge, executable_path=C:/researcher3rd/fpf/gpt_processor_main.py
2025-05-01 22:43:31,780 - gpt_processor_installer_gui - DEBUG - Input directory contents: ['standard_prompt.txt']
2025-05-01 22:43:31,780 - gpt_processor_installer_gui - DEBUG - Running command: ['python', 'C:/researcher3rd/fpf/gpt_processor_main.py', '--prompt', 'C:/researcher3rd/test4fpf\\filepromptforge\\prompts\\standard_prompt.txt', '--input_dir', 'C:/researcher3rd/test4fpf\\filepromptforge\\input', '--output_dir', 'C:/researcher3rd/test4fpf\\filepromptforge\\output']
2025-05-01 22:43:33,323 - gpt_processor_installer_gui - DEBUG - Command output: 
2025-05-01 22:43:33,323 - gpt_processor_installer_gui - DEBUG - Command error: Traceback (most recent call last):
  File "C:\researcher3rd\fpf\gpt_processor_main.py", line 19, in <module>
    from openai.error import OpenAIError, RateLimitError
ModuleNotFoundError: No module named 'openai.error'

2025-05-01 22:43:33,328 - gpt_processor_installer_gui - ERROR - Subprocess error: Command '['python', 'C:/researcher3rd/fpf/gpt_processor_main.py', '--prompt', 'C:/researcher3rd/test4fpf\\filepromptforge\\prompts\\standard_prompt.txt', '--input_dir', 'C:/researcher3rd/test4fpf\\filepromptforge\\input', '--output_dir', 'C:/researcher3rd/test4fpf\\filepromptforge\\output']' returned non-zero exit status 1.
2025-05-01 22:43:33,328 - gpt_processor_installer_gui - ERROR - Command output: 
2025-05-01 22:43:33,328 - gpt_processor_installer_gui - ERROR - Command stderr: Traceback (most recent call last):
  File "C:\researcher3rd\fpf\gpt_processor_main.py", line 19, in <module>
    from openai.error import OpenAIError, RateLimitError
ModuleNotFoundError: No module named 'openai.error'

